2024-12-17 13:00:11,321 - INFO - Trading Bot Initialized.
2024-12-17 13:00:11,330 - INFO - Configuration loaded successfully.
2024-12-17 13:00:26,037 - INFO - Remaining amount: 1, Order size: 0.1
2024-12-17 13:00:30,838 - ERROR - Error placing XT market order: Expecting value: line 1 column 1 (char 0)
2024-12-17 13:00:30,841 - INFO - Remaining amount: 0.9, Order size: 0.1
2024-12-17 13:00:35,776 - ERROR - Error placing XT market order: Expecting value: line 1 column 1 (char 0)
2024-12-17 13:00:35,779 - INFO - Remaining amount: 0.8, Order size: 0.1
2024-12-17 13:00:41,005 - ERROR - Error placing XT market order: Expecting value: line 1 column 1 (char 0)
2024-12-17 13:00:41,008 - INFO - Remaining amount: 0.7, Order size: 0.1
2024-12-17 13:08:13,124 - INFO - Trading Bot Initialized.
2024-12-17 13:08:13,127 - INFO - Configuration loaded successfully.
2024-12-17 13:08:28,360 - INFO - Remaining amount: 1, Order size: 0.1
2024-12-17 13:08:33,498 - ERROR - Error placing XT market order: Expecting value: line 1 column 1 (char 0)
2024-12-17 13:08:33,500 - INFO - Remaining amount: 0.9, Order size: 0.1
2024-12-17 13:08:38,054 - ERROR - Error placing XT market order: Expecting value: line 1 column 1 (char 0)
2024-12-17 13:08:38,057 - INFO - Remaining amount: 0.8, Order size: 0.1
2024-12-17 13:11:56,525 - INFO - Trading Bot Initialized.
2024-12-17 13:11:56,531 - INFO - Configuration loaded successfully.
2024-12-17 13:12:10,044 - INFO - Remaining amount: 1, Order size: 0.1
2024-12-17 13:12:15,180 - ERROR - XT API call failed with status code 503
2024-12-17 13:12:15,182 - INFO - Remaining amount: 0.9, Order size: 0.1
2024-12-17 13:12:20,308 - ERROR - XT API call failed with status code 503
2024-12-17 13:12:20,309 - INFO - Remaining amount: 0.8, Order size: 0.1
2024-12-17 13:21:57,480 - INFO - Trading Bot Initialized.
2024-12-17 13:21:57,486 - INFO - Configuration loaded successfully.
2024-12-17 13:22:11,851 - INFO - Remaining amount: 1, Order size: 0.1
2024-12-17 13:22:17,230 - ERROR - XT API call failed with status code 503
2024-12-17 13:22:17,233 - INFO - Remaining amount: 0.9, Order size: 0.1
2024-12-17 20:22:23,695 - INFO - Trading Bot Initialized.
2024-12-17 20:22:23,707 - INFO - Configuration loaded successfully.
2024-12-17 20:22:43,116 - INFO - Trading Bot Initialized.
2024-12-17 20:22:43,123 - INFO - Configuration loaded successfully.
2024-12-17 20:24:53,314 - INFO - Remaining amount: 1, Order size: 0.1
2024-12-17 20:24:56,319 - ERROR - XT API call failed with status code 503
2024-12-17 20:24:56,321 - INFO - Remaining amount: 0.9, Order size: 0.1
2024-12-17 20:24:59,375 - ERROR - XT API call failed with status code 503
2024-12-17 20:24:59,378 - INFO - Remaining amount: 0.8, Order size: 0.1
2024-12-17 20:25:02,870 - ERROR - XT API call failed with status code 503
2024-12-17 20:25:02,872 - INFO - Remaining amount: 0.7, Order size: 0.1
2024-12-17 20:25:06,357 - ERROR - XT API call failed with status code 503
2024-12-17 20:25:06,359 - INFO - Remaining amount: 0.6, Order size: 0.1
2024-12-17 20:25:09,124 - ERROR - XT API call failed with status code 503
2024-12-17 20:25:09,126 - INFO - Remaining amount: 0.5, Order size: 0.1
2024-12-17 20:25:11,688 - ERROR - XT API call failed with status code 503
2024-12-17 20:25:11,689 - INFO - Remaining amount: 0.4, Order size: 0.1
2024-12-17 20:25:14,086 - ERROR - XT API call failed with status code 503
2024-12-17 20:25:14,088 - INFO - Remaining amount: 0.3, Order size: 0.1
2024-12-17 20:25:16,660 - ERROR - XT API call failed with status code 503
2024-12-17 20:25:16,662 - INFO - Remaining amount: 0.2, Order size: 0.1
2024-12-17 20:25:19,559 - ERROR - XT API call failed with status code 503
2024-12-17 20:25:19,562 - INFO - Remaining amount: 0.1, Order size: 0.1
2024-12-17 20:25:22,119 - ERROR - XT API call failed with status code 503
2024-12-17 20:25:22,121 - INFO - Trading completed.
2024-12-18 06:22:20,163 - INFO - Trading Bot Initialized.
2024-12-18 06:22:20,167 - INFO - Configuration loaded successfully.
2024-12-18 06:22:21,329 - INFO - Authenticating XT WebSocket
2024-12-18 06:22:21,670 - ERROR - _GatheringFuture exception was never retrieved
future: <_GatheringFuture finished exception=CancelledError()>
Traceback (most recent call last):
  File "/home/awoyemivictora/clients/seena-houman-arbitrage-bot/client_bot.py", line 1893, in <module>
    asyncio.run(main())
  File "/usr/lib/python3.10/asyncio/runners.py", line 44, in run
    return loop.run_until_complete(main)
  File "/usr/lib/python3.10/asyncio/base_events.py", line 649, in run_until_complete
    return future.result()
  File "/home/awoyemivictora/clients/seena-houman-arbitrage-bot/client_bot.py", line 1873, in main
    await websocket_tasks()
TypeError: '_GatheringFuture' object is not callable

During handling of the above exception, another exception occurred:

Traceback (most recent call last):
  File "/home/awoyemivictora/clients/seena-houman-arbitrage-bot/client_bot.py", line 1788, in fetch_kucoin_data
    await subscribe_to_kucoin_level2(symbol)  # Assuming this updates order_books["kucoin"]
  File "/home/awoyemivictora/clients/seena-houman-arbitrage-bot/client_bot.py", line 1021, in subscribe_to_kucoin_level2
    async with websockets.connect(stream_url, ping_interval=30, ping_timeout=10) as websocket:
  File "/home/awoyemivictora/clients/seena-houman-arbitrage-bot/venv/lib/python3.10/site-packages/websockets/asyncio/client.py", line 485, in __aenter__
    return await self
  File "/home/awoyemivictora/clients/seena-houman-arbitrage-bot/venv/lib/python3.10/site-packages/websockets/asyncio/client.py", line 442, in __await_impl__
    self.connection = await self.create_connection()
  File "/home/awoyemivictora/clients/seena-houman-arbitrage-bot/venv/lib/python3.10/site-packages/websockets/asyncio/client.py", line 368, in create_connection
    _, connection = await loop.create_connection(factory, **kwargs)
  File "/usr/lib/python3.10/asyncio/base_events.py", line 1036, in create_connection
    infos = await self._ensure_resolved(
  File "/usr/lib/python3.10/asyncio/base_events.py", line 1418, in _ensure_resolved
    return await loop.getaddrinfo(host, port, family=family, type=type,
  File "/usr/lib/python3.10/asyncio/base_events.py", line 863, in getaddrinfo
    return await self.run_in_executor(
asyncio.exceptions.CancelledError

During handling of the above exception, another exception occurred:

asyncio.exceptions.CancelledError
2024-12-18 06:29:35,340 - INFO - Trading Bot Initialized.
2024-12-18 06:29:35,345 - INFO - Configuration loaded successfully.
2024-12-18 06:29:46,892 - INFO - Authenticating XT WebSocket
2024-12-18 06:29:46,894 - INFO - Remaining amount: 1, Order size: 0.1
2024-12-18 06:29:49,573 - ERROR - XT API call failed with status code 503
2024-12-18 06:29:49,575 - INFO - Remaining amount: 0.9, Order size: 0.1
2024-12-18 06:29:52,236 - ERROR - XT API call failed with status code 503
2024-12-18 06:29:52,239 - INFO - Remaining amount: 0.8, Order size: 0.1
2024-12-18 06:29:54,778 - ERROR - XT API call failed with status code 503
2024-12-18 06:29:54,779 - INFO - Remaining amount: 0.7, Order size: 0.1
2024-12-18 06:29:56,992 - INFO - Closing WebSocket connections...
2024-12-18 06:29:57,086 - ERROR - Task exception was never retrieved
future: <Task finished name='Task-1' coro=<main() done, defined at /home/awoyemivictora/clients/seena-houman-arbitrage-bot/client_bot.py:1946> exception=KeyboardInterrupt()>
Traceback (most recent call last):
  File "/home/awoyemivictora/clients/seena-houman-arbitrage-bot/client_bot.py", line 1979, in <module>
    asyncio.run(main())
  File "/usr/lib/python3.10/asyncio/runners.py", line 47, in run
    _cancel_all_tasks(loop)
  File "/usr/lib/python3.10/asyncio/runners.py", line 63, in _cancel_all_tasks
    loop.run_until_complete(tasks.gather(*to_cancel, return_exceptions=True))
  File "/usr/lib/python3.10/asyncio/base_events.py", line 636, in run_until_complete
    self.run_forever()
  File "/usr/lib/python3.10/asyncio/base_events.py", line 603, in run_forever
    self._run_once()
  File "/usr/lib/python3.10/asyncio/base_events.py", line 1909, in _run_once
    handle._run()
  File "/usr/lib/python3.10/asyncio/events.py", line 80, in _run
    self._context.run(self._callback, *self._args)
  File "/home/awoyemivictora/clients/seena-houman-arbitrage-bot/client_bot.py", line 1966, in main
    await asyncio.gather(
  File "/usr/lib/python3.10/asyncio/runners.py", line 44, in run
    return loop.run_until_complete(main)
  File "/usr/lib/python3.10/asyncio/base_events.py", line 636, in run_until_complete
    self.run_forever()
  File "/usr/lib/python3.10/asyncio/base_events.py", line 603, in run_forever
    self._run_once()
  File "/usr/lib/python3.10/asyncio/base_events.py", line 1909, in _run_once
    handle._run()
  File "/usr/lib/python3.10/asyncio/events.py", line 80, in _run
    self._context.run(self._callback, *self._args)
  File "/home/awoyemivictora/clients/seena-houman-arbitrage-bot/client_bot.py", line 363, in manage_trading
    await execute_market_order(
  File "/home/awoyemivictora/clients/seena-houman-arbitrage-bot/client_bot.py", line 318, in execute_market_order
    return await place_market_order_xt(
  File "/home/awoyemivictora/clients/seena-houman-arbitrage-bot/client_bot.py", line 1265, in place_market_order_xt
    response = requests.post(endpoint, data=params, headers=headers)
  File "/home/awoyemivictora/clients/seena-houman-arbitrage-bot/venv/lib/python3.10/site-packages/requests/api.py", line 115, in post
    return request("post", url, data=data, json=json, **kwargs)
  File "/home/awoyemivictora/clients/seena-houman-arbitrage-bot/venv/lib/python3.10/site-packages/requests/api.py", line 59, in request
    return session.request(method=method, url=url, **kwargs)
  File "/home/awoyemivictora/clients/seena-houman-arbitrage-bot/venv/lib/python3.10/site-packages/requests/sessions.py", line 589, in request
    resp = self.send(prep, **send_kwargs)
  File "/home/awoyemivictora/clients/seena-houman-arbitrage-bot/venv/lib/python3.10/site-packages/requests/sessions.py", line 703, in send
    r = adapter.send(request, **kwargs)
  File "/home/awoyemivictora/clients/seena-houman-arbitrage-bot/venv/lib/python3.10/site-packages/requests/adapters.py", line 667, in send
    resp = conn.urlopen(
  File "/home/awoyemivictora/clients/seena-houman-arbitrage-bot/venv/lib/python3.10/site-packages/urllib3/connectionpool.py", line 789, in urlopen
    response = self._make_request(
  File "/home/awoyemivictora/clients/seena-houman-arbitrage-bot/venv/lib/python3.10/site-packages/urllib3/connectionpool.py", line 536, in _make_request
    response = conn.getresponse()
  File "/home/awoyemivictora/clients/seena-houman-arbitrage-bot/venv/lib/python3.10/site-packages/urllib3/connection.py", line 507, in getresponse
    httplib_response = super().getresponse()
  File "/usr/lib/python3.10/http/client.py", line 1375, in getresponse
    response.begin()
  File "/usr/lib/python3.10/http/client.py", line 318, in begin
    version, status, reason = self._read_status()
  File "/usr/lib/python3.10/http/client.py", line 279, in _read_status
    line = str(self.fp.readline(_MAXLINE + 1), "iso-8859-1")
  File "/usr/lib/python3.10/socket.py", line 705, in readinto
    return self._sock.recv_into(b)
  File "/usr/lib/python3.10/ssl.py", line 1303, in recv_into
    return self.read(nbytes, buffer)
  File "/usr/lib/python3.10/ssl.py", line 1159, in read
    return self._sslobj.read(len, buffer)
KeyboardInterrupt
